### 출처
* [python surpress](https://medium.com/@akulahemanth/pythons-contextlib-suppress-a-clean-way-to-handle-exceptions-db7439e32025)
* [when to use raise from](https://stackoverflow.com/questions/24752395/python-raise-from-usage)
___
### 개요
* [[#surpress]]
* [[#raise from]]
___
### surpress

`surpress`는 파이썬의 예외처리 방법 중 하나로 **`surpress`를 활용할 경우 블럭 내부에서 발생하는 예외를 무시하고 넘기는 처리가 가능하다.** `surpress`의 문법은 아래와 같으며 이는 **아무런 예외 처리도 진행하지 않는 `try-except` 구문과 동일하게 동작한다.**

```python
from contextlib import surpress

#both are same
with surpress(Exceoption):
	do_some()

try:
	do_some()
except Exception:
	pass
```

`surpress`는 적절히 활용하면 코드를 우아하게 만드는데 큰 도움을 준다. 파일을 삭제하는 상황을 생각해보자. 파일이 존재하면 삭제하고 존재하지 않을시 넘기면 된다. 이때 `try-catch`보다 `surpress`를 사용하면 더욱 간단한 코드 표현이 가능해진다.

```python
try:
	os.remove("some file")

except FileNotFoundError:
	pass

with surpress(FileNotFoundError): #1줄로 코드를 단축할 수 있다.
	os.remove("some file")
```

이런 경우도 생각해볼 수 있다. 네트워크 요청에서 타임아웃이 발생한 상황을 생각해보자. 일반적으로 타임아웃이 발생한 경우에는 단순 재시도만 진행하면 된다.

```python
   for _ in range(3):
        session = await create_logined_session(STUDENT_ID, USAINT_SECRET, token)
        async with session:
            try:
                with suppress(TimeoutError):  # 타임아웃인 경우 그냥 다시 진행
                    cache_data: list[dict] = await get_all_date_reservations(
                        session, room_type_id
                    )  # 예약 현황 추출
                token = session._client.headers["pyxis-auth-token"]  # 기존 토큰 재활용
                return cache_data

            except AssertionError:  # 인증 오류가 발생한 경우
                token = None  # 토
```

위는 실제 사용중인 코드로 타임아웃이 발생했을 때는 오류를 무시하고 반복을 진행한다. 만약 `try-except` 패턴을 사용했더라면 코드에 블럭이 하나 더 발생하며 코드의 생김새가 지저분해졌을 것이다.

>[!info]
>**요약하면 `surpress`는 별도의 예외처리 로직이 요구되지 않을 때 간결한 코드 작성에 도움을 주는 기법이다.**

 추가적으로 생각해 볼만한 부분은 `finally` 등의 구문 없어 코드의 실행흐름을 빠르게 파악할 수 있다는 것이다. **`surpress` 컨텍스트 매니저 내부에 놓인 구문은 특정 예외가 발생 되더라도 계속해서 실행 되기에 프로그램이 어떤 순서로 진행되는지 한눈에 파악할 수 있다.**
___
### raise from

파이썬의 예외는 모두 `BaseExceoption을` 상속하고 해당 클래스는 `__cause__`와 `__context__` 라는 속성을 갖는다. 이때 **cause는 예외가 발생하게 된 원인을 말하고 context는 현재 예외가 발생했을 때 이미 발생해있는 또 다른 예외를 말한다**. 

**`raise`를 통한 신규 예외가 발생했을 때 신규 예외 객체의 `__context__` 속성은 이전에 발생한 예외의 `__context__`로 부터 자동적으로 설정된다.** 이에 따라 해당 예외가 어떠한 요인으로 인해 발생 했는지를 명시하는 것에는 어려움이 존재한다.

```python
try:
    print("No exception")
    raise ValueError("Value Error1")

except ValueError as e:
    try:
        print(e.__cause__) #None
        print(e.__context__) #None
        raise IndexError("Index Error1")

    except IndexError as e:
        print(e.__cause__) #None
        print(e.__context__) #ValueError

```

위의 코드를 동작 시켜보면 예외가 발생했을 때 context 속성에만 값이 추가되는 것을 확인 할 수 있다. 컨텍스트에 값이 계속해서 증가하는 방식으로 출력돼며 예외가 많을 경우 길게 늘어선 예외 영수증을 확인해 볼 수 있다.

```python
Traceback (most recent call last):
  File "/Users/jin/Library/Mobile Documents/iCloud~md~obsidian/Documents/my_study/python/code/raise_from.py", line 3, in <module>
    raise ValueError("Value Error1")
ValueError: Value Error1

During handling of the above exception, another exception occurred:

Traceback (most recent call last):
  File "/Users/jin/Library/Mobile Documents/iCloud~md~obsidian/Documents/my_study/python/code/raise_from.py", line 9, in <module>
    raise IndexError("Index Error1")
IndexError: Index Error1

During handling of the above exception, another exception occurred:

Traceback (most recent call last):
  File "/Users/jin/Library/Mobile Documents/iCloud~md~obsidian/Documents/my_study/python/code/raise_from.py", line 14, in <module>
    raise IndexError
IndexError
```

이를 해결하고자 `raise from` 을 활용한다. `raise from`을 활용할 경우 `__cause__`에 `from` 뒤에 위치한 예외 값이 들어가며 해당 예외의 발생원인으로 하나의 예외를 특정하는 것이 가능해진다. 또한 이때 `__surpress_context__` 값이 참으로 설정돼 **이후 `from` 절의 예외가 발생할 때 이전까지의 발생한 예외는 출력되지 않고 `from`절 이후에 존재하는 예외만 출력된다**

```python
try:
    print("No exception")
    raise ValueError("Value Error1")

except ValueError as e:
    try:
        print(e.__cause__)
        print(e.__context__)
        raise IndexError("Index Error1") from FileExistsError("This is reason!!")

    except IndexError as e:
        print(e.__cause__)
        print(e.__context__)
        print(e.__suppress_context__)
```

출력 값은 아래와 같다.
```python
No exception
None
None
This is reason!! #cause 값이 초기화 된 것을 확인 가능하다
Value Error1 #컨텍스트에 인덱스에러가 없고 벨류 에러만 존재한다
True #컨텍스트 압축 여부가 참이 된다
```

만약 예외를 발생시키면 아래와 같이 `Traceback`이 출력된다.

```python
FileExistsError: This is reason!!

**==The above exception was the direct cause of the following exception:==**

Traceback (most recent call last):
  File "/Users/jin/Library/Mobile Documents/iCloud~md~obsidian/Documents/my_study/python/code/raise_from.py", line 9, in <module>
    raise IndexError("Index Error1") from FileExistsError("This is reason!!")
IndexError: Index Error1

During handling of the above exception, another exception occurred:

Traceback (most recent call last):
  File "/Users/jin/Library/Mobile Documents/iCloud~md~obsidian/Documents/my_study/python/code/raise_from.py", line 15, in <module>
    raise Exception
Exception

```

유심히 살펴볼 부분은 파일 예외 이전에 발생한 예외들이 전부 출력되지 않는다는 것이다. 이를 활용해 <span class="red red-bg">예외 체인이 적나라하게 노출되는 현상을 감출 수 있고 디버깅시 명확한 원인 파악이 가능해진다.</span>
from  절에는 None을 위치시킬 수도 있는데 이를 활용하면 더욱 효율적으로 예외 체인을 은닉화하는 것이 가능하다.

```python
try:
    print("No exception")
    raise ValueError("Value Error1")

except ValueError as e:
    try:
        print(e.__cause__)
        print(e.__context__)
        raise IndexError("Index Error1") from None #예외의 발생원인을 None으로 한다.

    except IndexError as e:
        print(e.__cause__)
        print(e.__context__)
        print(e.__suppress_context__)
        raise Exception

```

결과는 아래와 같다. 확인해보면 IndexError의 원인이 명확히 파악 가능하던 이전과 달리 IndexError가 어디서 부터의 전파로 인해 발생 됐는지 파악하기 어려워졌다. 이렇게 하면 **예외 체인을 요약하거나 유저에게 프로그램의 정보를 지나치게 많이 제공하는 것을 방지할 수 있다.**

```python
No exception
None
None
None
Value Error1
True
Traceback (most recent call last):
  File "/Users/jin/Library/Mobile Documents/iCloud~md~obsidian/Documents/my_study/python/code/raise_from.py", line 9, in <module>
    raise IndexError("Index Error1") from None
IndexError: Index Error1

During handling of the above exception, another exception occurred:

Traceback (most recent call last):
  File "/Users/jin/Library/Mobile Documents/iCloud~md~obsidian/Documents/my_study/python/code/raise_from.py", line 15, in <module>
    raise Exception
Exception
```

>[!info]
>**raise from을 활용하면 예외 체인의 흐름을 끊고 해당 예외의 원인을 명확히 특정하거나 은닉화 하는 것이 가능하다.**